<?xml version="1.0" ?>
<!-- =================================================================================== -->
<!-- |    This document was autogenerated by xacro from only_arm.urdf.xacro            | -->
<!-- |    EDITING THIS FILE BY HAND IS NOT RECOMMENDED                                 | -->
<!-- =================================================================================== -->
<!--
  Copyright (c) 2011, PAL Robotics, S.L.
  All rights reserved.

  This work is licensed under the Creative Commons Attribution-NonCommercial-NoDerivs 3.0 Unported License.
  To view a copy of this license, visit http://creativecommons.org/licenses/by-nc-nd/3.0/ or send a letter to
  Creative Commons, 444 Castro Street, Suite 900, Mountain View, California, 94041, USA.
-->
<robot name="tiago" xmlns:xacro="http://ros.org/wiki/xacro">
  <link name="torso_lift_link" />
  <!-- Arm -->
  <!--File includes-->
  <!--File includes-->
  <!--Constant parameters-->
  <!--Constant parameters-->
  <!-- Generic simulator_gazebo plugins -->
  
  <!-- define global properties -->
  <!-- Materials for visualization -->
  <material name="Blue">
    <color rgba="0.0 0.0 0.8 1.0"/>
  </material>
  <material name="Green">
    <color rgba="0.0 0.8 0.0 1.0"/>
  </material>
  <material name="Grey">
    <color rgba="0.7 0.7 0.7 1.0"/>
  </material>
  <material name="LightGrey">
    <color rgba="0.9 0.9 0.9 1.0"/>
  </material>
  <material name="DarkGrey">
    <color rgba="0.1 0.1 0.1 1.0"/>
  </material>
  <material name="Red">
    <color rgba="0.8 0.0 0.0 1.0"/>
  </material>
  <material name="White">
    <color rgba="1.0 1.0 1.0 1.0"/>
  </material>
  <material name="Yellow">
    <color rgba="0.96 0.88 0.14 1.0"/>
  </material>
  <!--************************-->
  <!--        SHOULDER        -->
  <!--************************-->
  <link name="arm_1_link">
    <inertial>
      <origin rpy="0 0 0" xyz="0.019568 -0.052265 0.008219"/>
      <mass value="2.108556"/>
      <inertia ixx="0.005489" ixy="-0.001537" ixz="-0.000404" iyy="0.002232" iyz="0.000996" izz="0.006068"/>
    </inertial>
    <!-- M90 module -->
    <visual>
      <origin rpy="0 0 0" xyz="0 0 0"/>
      <geometry>
        <mesh filename="package://tiago_description/meshes/arm/arm_1.stl" scale="1 1 1"/>
      </geometry>
      <material name="Orange"/>
    </visual>
    <collision>
      <origin rpy="0 0 0" xyz="0 0 0"/>
      <geometry>
        <mesh filename="package://tiago_description/meshes/arm/arm_1.stl" scale="1 1 1"/>
      </geometry>
    </collision>
  </link>
  
  <joint name="arm_1_joint" type="revolute">
    <parent link="torso_lift_link"/>
    <child link="arm_1_link"/>
    <origin rpy="0 0 0" xyz="0.155 0.011 -0.152"/>
    <axis xyz="0 0 1"/>
    <limit effort="39.0" lower="0.0" upper="2.87979326579" velocity="2.7"/>
    <dynamics damping="1.0" friction="1.0"/>
    <safety_controller k_position="20" k_velocity="20" soft_lower_limit="0.0" soft_upper_limit="2.85979326579"/>
  </joint>
  <link name="arm_2_link">
    <inertial>
      <origin rpy="0 0 0" xyz="0.01435 -0.06294 0.01039"/>
      <mass value="1.58751"/>
      <inertia ixx="0.002253374" ixy="-0.00185617271" ixz="0.00023094382" iyy="0.01079198201" iyz="-0.00004741252" izz="0.0112248261"/>
    </inertial>
    <visual>
      <origin rpy="3.14159265359 0.0 -1.57079632679" xyz="0 0 0"/>
      <geometry>
        <mesh filename="package://tiago_description/meshes/arm/arm_2.dae" scale="1 1 1"/>
      </geometry>
      <material name="DarkGrey"/>
    </visual>
    <collision>
      <origin rpy="3.14159265359 0.0 -1.57079632679" xyz="0 0 0"/>
      <geometry>
        <mesh filename="package://tiago_description/meshes/arm/arm_2_collision.stl" scale="1 1 1"/>
      </geometry>
    </collision>
  </link>
  <joint name="arm_2_joint" type="revolute">
    <parent link="arm_1_link"/>
    <child link="arm_2_link"/>
    <origin rpy="1.57079632679 0.0 -1.57079632679" xyz="0.009 -0.125 -0.032"/>
    <axis xyz="0 0 1"/>
    <limit effort="39.0" lower="-1.62315620435" upper="1.308996939" velocity="3.66"/>
    <dynamics damping="1.0" friction="1.0"/>
    <safety_controller k_position="20" k_velocity="20" soft_lower_limit="-1.60315620435" soft_upper_limit="1.288996939"/>
  </joint>
  <link name="arm_3_link">
    <inertial>
      <origin rpy="0 0 0" xyz="0.00557 -0.01042 -0.10388"/>
      <mass value="1.79881"/>
      <inertia ixx="0.02682610467" ixy="-0.00019692212" ixz="-0.0015045329" iyy="0.02638053578" iyz="0.00263989274" izz="0.002385016"/>
    </inertial>
    <visual>
      <origin rpy="0 0 0" xyz="0 0 -0.055"/>
      <geometry>
        <mesh filename="package://tiago_description/meshes/arm/arm_3.dae" scale="1 1 1"/>
      </geometry>
      <material name="DarkGrey"/>
    </visual>
    <visual>
      <origin rpy="0 0 0" xyz="0 0 0"/>
      <geometry>
        <cylinder length="0.07" radius="0.05"/>
      </geometry>
      <material name="DarkGrey"/>
    </visual>
    <collision>
      <origin rpy="0 0 0" xyz="0 0 -0.055"/>
      <geometry>
        <mesh filename="package://tiago_description/meshes/arm/arm_3_collision.stl" scale="1 1 1"/>
      </geometry>
    </collision>
    <collision>
      <origin rpy="0 0 0" xyz="0 0 0"/>
      <geometry>
        <cylinder length="0.07" radius="0.05"/>
      </geometry>
      <material name="DarkGrey"/>
    </collision>
  </link>
  <joint name="arm_3_joint" type="revolute">
    <parent link="arm_2_link"/>
    <child link="arm_3_link"/>
    <origin rpy="0.0 -1.57079632679 0" xyz="0.142 -0.02 0"/>
    <axis xyz="0 0 1"/>
    <limit effort="17.86" lower="-3.49065850399" upper="1.57079632679" velocity="4.58"/>
    <dynamics damping="1.0" friction="1.0"/>
    <safety_controller k_position="20" k_velocity="20" soft_lower_limit="-3.47065850399" soft_upper_limit="1.55079632679"/>
  </joint>
  <!--************************-->
  <!--        ELBOW           -->
  <!--************************-->
  <link name="arm_4_link">
    <inertial>
      <origin rpy="0 0 0" xyz="-0.06578 0.0126 0.01194"/>
      <mass value="1.35076"/>
      <inertia ixx="0.00220509703" ixy="-0.00165490069" ixz="-0.0002277335" iyy="0.01177626386" iyz="0.00003472435" izz="0.0120918757"/>
    </inertial>
    <visual>
      <origin rpy="0 0 0" xyz="0 0 0"/>
      <geometry>
        <mesh filename="package://tiago_description/meshes/arm/arm_4.dae" scale="1 1 1"/>
      </geometry>
      <material name="DarkGrey"/>
    </visual>
    <visual>
      <origin rpy="0 1.57079632679 0" xyz="-0.15 0.02 0"/>
      <geometry>
        <cylinder length="0.07" radius="0.05"/>
      </geometry>
      <material name="DarkGrey"/>
    </visual>
    <collision>
      <origin rpy="0 0 0" xyz="0 0 0"/>
      <geometry>
        <mesh filename="package://tiago_description/meshes/arm/arm_4_collision.stl" scale="1 1 1"/>
      </geometry>
    </collision>
    <collision>
      <origin rpy="0 1.57079632679 0" xyz="-0.15 0.02 0"/>
      <geometry>
        <cylinder length="0.07" radius="0.05"/>
      </geometry>
      <material name="DarkGrey"/>
    </collision>
  </link>
  <joint name="arm_4_joint" type="revolute">
    <parent link="arm_3_link"/>
    <child link="arm_4_link"/>
    <origin rpy="0 -1.57079632679 0" xyz="0 -0.02 -0.168"/>
    <axis xyz="0 0 1"/>
    <limit effort="17.86" lower="-1.57079632679" upper="2.35619449019" velocity="4.58"/>
    <dynamics damping="1.0" friction="1.0"/>
    <safety_controller k_position="20" k_velocity="20" soft_lower_limit="-1.59079632679" soft_upper_limit="2.33619449019"/>
  </joint>
  
  
  
  
  
  
  
  
  <!--************************-->
  <!--        WRIST           -->
  <!--************************-->
  <!--************************-->
  <!--        WRIST           -->
  <!--************************-->
  <link name="arm_5_link">
    <inertial>
      <origin rpy="0 0 0" xyz="-0.00084 0.00001 0.07797"/>
      <mass value="1.32698"/>
      <inertia ixx="0.01049566566" ixy="-0.00000316264" ixz="-0.00012548144" iyy="0.01028836655" iyz="0.0000027891" izz="0.00094419873"/>
    </inertial>
    <visual>
      <origin rpy="0 0 0" xyz="0 0 0"/>
      <geometry>
        <mesh filename="package://tiago_description/meshes/arm/arm_5.dae" scale="1 1 -1.0"/>
      </geometry>
      <material name="LightGrey"/>
    </visual>
    <collision>
      <origin rpy="0 0 0" xyz="0 0 0"/>
      <geometry>
        <mesh filename="package://tiago_description/meshes/arm/arm_5_collision.stl" scale="1 1 -1.0"/>
      </geometry>
    </collision>
  </link>
  <joint name="arm_5_joint" type="revolute">
    <parent link="arm_4_link"/>
    <child link="arm_5_link"/>
    <origin rpy="0.0 -1.57079632679 0.0" xyz="-0.168 0.02 0"/>
    <axis xyz="0 0 1"/>
    <limit effort="3" lower="-2.09439510239" upper="2.09439510239" velocity="1.95"/>
    <dynamics damping="1.0" friction="1.0"/>
    <safety_controller k_position="20" k_velocity="20" soft_lower_limit="-2.07439510239" soft_upper_limit="2.07439510239"/>
  </joint>
  <link name="arm_6_link">
    <inertial>
      <origin rpy="0 0 0" xyz="-0.000014 -0.00368 1e-05"/>
      <mass value="0.35781"/>
      <inertia ixx="0.00016489507" ixy="0.0000002779" ixz="0.00000009308" iyy="0.00013154987" iyz="0.00000007106" izz="0.00011998795"/>
    </inertial>
    <visual>
      <origin rpy="0 0 0" xyz="0 0 0"/>
      <geometry>
        <mesh filename="package://tiago_description/meshes/arm/arm_6.dae" scale="1 1 -1.0"/>
      </geometry>
      <material name="LightGrey"/>
    </visual>
    <collision>
      <origin rpy="0 0 0" xyz="0 0 0"/>
      <geometry>
        <cylinder length="0.0385" radius="0.04"/>
      </geometry>
    </collision>
  </link>
  <joint name="arm_6_joint" type="revolute">
    <parent link="arm_5_link"/>
    <child link="arm_6_link"/>
    <origin rpy="-1.57079632679 0 0" xyz="0 0 0.15"/>
    <axis xyz="0 0 1"/>
    <limit effort="6.6" lower="-1.57079632679" upper="1.57079632679" velocity="1.76"/>
    <dynamics damping="1.0" friction="1.0"/>
    <safety_controller k_position="20" k_velocity="20" soft_lower_limit="-1.55079632679" soft_upper_limit="1.55079632679"/>
  </joint>
  <link name="arm_7_link">
    <inertial>
      <origin rpy="0 0 0" xyz="0 -0.00005 -0.01573"/>
      <mass value="0.10721"/>
      <inertia ixx="0.00008977003" ixy="-0.00000000001" ixz="0.0" iyy="0.00008968773" iyz="-0.00000021816" izz="0.00000951878"/>
    </inertial>
    <visual>
      <origin rpy="0 0 0" xyz="0 0 0.046"/>
      <geometry>
        <cylinder length="0.005" radius="0.02"/>
      </geometry>
      <material name="DarkGrey"/>
    </visual>
    <collision>
      <origin rpy="0 0 0" xyz="0 0 0.0345"/>
      <geometry>
        <cylinder length="0.023" radius="0.02"/>
      </geometry>
    </collision>
  </link>
  <joint name="arm_7_joint" type="revolute">
    <parent link="arm_6_link"/>
    <child link="arm_7_link"/>
    <origin rpy="1.57079632679 0 0" xyz="0 0 0"/>
    <axis xyz="0 0 1"/>
    <limit effort="6.6" lower="-2.09439510239" upper="2.09439510239" velocity="1.76"/>
    <dynamics damping="1.0" friction="1.0"/>
    <safety_controller k_position="20" k_velocity="20" soft_lower_limit="-2.07439510239" soft_upper_limit="2.07439510239"/>
  </joint>
  
  
  
  
  
  
  <!-- extensions -->
  
  
  <!--***********************-->
  <!--        TOOL           -->
  <!--***********************-->
  <link name="arm_tool_link">
    <inertial>
      <mass value="0.1"/>
      <inertia ixx="0.0" ixy="0.0" ixz="0.0" iyy="0.0" iyz="0.0" izz="0.0"/>
    </inertial>
    <visual>
      <origin rpy="0 1.57079632679 0" xyz="0.001 0 0"/>
      <geometry>
        <cylinder length="0.005" radius="0.01"/>
      </geometry>
      <material name="LightGrey"/>
    </visual>
    <collision>
      <origin rpy="0 1.57079632679 0" xyz="0.001 0 0"/>
      <geometry>
        <cylinder length="0.005" radius="0.01"/>
      </geometry>
    </collision>
  </link>
  <joint name="arm_tool_joint" type="fixed">
    <parent link="arm_7_link"/>
    <child link="arm_tool_link"/>
    <origin rpy="1.57079632679 -1.57079632679 3.14159265359" xyz="0 0 0.046"/>
  </joint>
  <!-- extensions -->
  
  
  
  
</robot>

